## Исключения (Exception)



```c#
try
{
    
}
catch (Exception e)
{
    Console.WriteLine(e.Message);
}
```



Выбрасывание исключений:

```c#
Exception ex = new Exception("Мое исключение");

try
{
    throw ex;
}
catch (Exception e)
{
	Console.WriteLine("Обработка исключения");
    Console.WriteLine(e.Message);
}
```



Выбрасывание исключений по слабой ссылке:

```c#
try
{
    throw new Exception("Мое исключение");
}
catch (Exception e)
{
	Console.WriteLine("Обработка исключения");
    Console.WriteLine(e.Message);
}
```



Формирование дополнительной информации об исключении:

```c#
public void MyMethod()
{
    Exception ex = new Exception("Мое исключение");
    
    ex.HelpLink = "http://MyCompy.com/ErrorService";
    ex.Data.Add("Причина исключения: ", "Тестовое исключение");
    ex.Data.Add("Время возникновения исключения: ", DateTime.Now);
    
    throw ex;
}
```



Создание пользовательских исключений:

```c#
class UserException: Exception
{
    public void Method()
    {
        Console.WriteLine("Мое исключение");
    }
}

class Program
{
    static void Main()
    {
        try
        {
            throw new UserException();
        }
        catch (UserException e)
        {
            Console.WriteLine("Обработка исключения");
   			e.Method();
        }
    }
}
```



Блок finally отрабатывает всегда:

```c#
try
{
    
}
catch (Exception e)
{
    Console.WriteLine("Обработка исключения");
}
finally
{
    Console.WriteLine("finally");
}
```

Блок finaly выполнится в любом случае, кроме ситуации, когда в блоке try сгенерируется исключение типа StackOverflowException.



Ошибки вроде переполнения стека не обрабатываются, программа аварийно закрывается.

```c#
Action m = null;
m = () => {
    Console.WriteLine("!!!!!!!!!!!!!!!!");
    m.Invoke();
};
m();
```



Обработчики исключений можно вкладывать в друг друга и передавать исключение вверх по стеку:

```c#
try
{
    try
    {
	
        try
        {
			throw new Exception("Мое исключение");
        }
        catch (Exception e)
        {
            Console.WriteLine("catch 1" + e.Message);
            throw; // Передаем вверх текущее исключение
        }
        finally
        {
            Console.WriteLine("finally 1");
        }
        
    }
    catch (Exception e)
    {
        Console.WriteLine("catch 2" + e.Message);
        throw;
    }
    finally
    {
        Console.WriteLine("finally 2");
         // В этом случае мы передаем вверх уже новое исключение
        throw new Exception("Новое исключение");
    }
}
catch (Exception e)
{
    Console.WriteLine("catch 3" + e.Message);
}
finally
{
    Console.WriteLine("finally 3");
}
```

